Workbook

Sheet Ana Veri
A1: Danışman | B1: Danışman Tipi | C1: Görev | D1: Danışmanlık Tarihi | E1: Yıl | F1: Çeyrek | G1: Danışmanlık Grubu | H1: Danışmanlık Adı | I1: Danışmanlık Alan Kurum | J1: Proje No | K1: Danışmanlık Yeri | L1: Danışmanlık Saati | M1: Katılımcı Sayısı | N1: Danışmanlık Günü | O1: İnsanxSaat | P1: İnsanxGün
A2: Buğra Doymaz | B2: Tam Zamanlı | C2: Teknisyen | D2: 45995 | E2: =+YEAR(D2) -> 2025 | F2: =+ROUNDUP(MONTH(D2)/3,0) -> 4 | G2: Öğren-Dönüş | H2: Saha Çalışması | I2: Külça Çelik Kapı | J2: KMF-2025-ÖDP-86-134 | K2: Kayseri | L2: 4 | M2: 10 | N2: =IFERROR(L2/8," ") -> 0.5 | O2: =M2*L2 -> 40 | P2: =+M2*N2 -> 5
A3: Onur Şahin | B3: Tam Zamanlı | C3: Stajyer | D3: 45995 | E3: =+YEAR(D3) -> 2025 | F3: =+ROUNDUP(MONTH(D3)/3,0) -> 4 | G3: Öğren-Dönüş | H3: Saha Çalışması | I3: Külça Çelik Kapı | J3: KMF-2025-ÖDP-86-134 | K3: Kayseri | L3: 4 | M3: 10 | N3: =IFERROR(L3/8," ") -> 0.5 | O3: =M3*L3 -> 40 | P3: =+M3*N3 -> 5
A4: Onur Kemaneci | B4: Tam Zamanlı | C4: Stajyer | D4: 45995 | E4: =+YEAR(D4) -> 2025 | F4: =+ROUNDUP(MONTH(D4)/3,0) -> 4 | G4: Öğren-Dönüş | H4: Saha Çalışması | I4: Külça Çelik Kapı | J4: KMF-2025-ÖDP-86-134 | K4: Kayseri | L4: 4 | M4: 10 | N4: =IFERROR(L4/8," ") -> 0.5 | O4: =M4*L4 -> 40 | P4: =+M4*N4 -> 5
A5: Onur Kemaneci | B5: Tam Zamanlı | C5: Stajyer | D5: 45994 | E5: =+YEAR(D5) -> 2025 | F5: =+ROUNDUP(MONTH(D5)/3,0) -> 4 | G5: Öğren-Dönüş | H5: Saha Çalışması | I5: Parteks | J5: KMF-2024-BUP-12-122 | K5: Kayseri | L5: 4 | M5: 10 | N5: =IFERROR(L5/8," ") -> 0.5 | O5: =M5*L5 -> 40 | P5: =+M5*N5 -> 5
A6: Ebru Takcı | B6: Tam Zamanlı | C6: Uzman | D6: 45996 | E6: =+YEAR(D6) -> 2025 | F6: =+ROUNDUP(MONTH(D6)/3,0) -> 4 | G6: Öğren-Dönüş | H6: Saha Çalışması | I6: Akyapı Lojistik | J6: KMF-2025-ÖDP-87-135 | K6: Kayseri | L6: 4 | M6: 10 | N6: =IFERROR(L6/8," ") -> 0.5 | O6: =M6*L6 -> 40 | P6: =+M6*N6 -> 5
A7: Buğra Doymaz | B7: Tam Zamanlı | C7: Teknisyen | D7: 45996 | E7: =+YEAR(D7) -> 2025 | F7: =+ROUNDUP(MONTH(D7)/3,0) -> 4 | G7: Öğren-Dönüş | H7: Saha Çalışması | I7: Akyapı Lojistik | J7: KMF-2025-ÖDP-87-135 | K7: Kayseri | L7: 4 | M7: 10 | N7: =IFERROR(L7/8," ") -> 0.5 | O7: =M7*L7 -> 40 | P7: =+M7*N7 -> 5
A8: Onur Kemaneci | B8: Tam Zamanlı | C8: Stajyer | D8: 45996 | E8: =+YEAR(D8) -> 2025 | F8: =+ROUNDUP(MONTH(D8)/3,0) -> 4 | G8: Öğren-Dönüş | H8: Saha Çalışması | I8: Külça Çelik Kapı | J8: KMF-2025-ÖDP-87-135 | K8: Kayseri | L8: 4 | M8: 10 | N8: =IFERROR(L8/8," ") -> 0.5 | O8: =M8*L8 -> 40 | P8: =+M8*N8 -> 5
A9: Mehmet Sürücü | B9: Tam Zamanlı | C9: Uzman | D9: 45978 | E9: 2025 | F9: =+ROUNDUP(MONTH(D9)/3,0) -> 4 | G9: Öğren-Dönüş | H9: Saha Çalışması | I9: Kartallar Damper | K9: Kayseri | L9: 4 | M9: 10 | N9: =IFERROR(L9/8," ") -> 0.5 | O9: =M9*L9 -> 40 | P9: =+M9*N9 -> 5
A10: Mehmet Sürücü | B10: Tam Zamanlı | C10: Uzman | D10: 46000 | E10: 2025 | F10: =+ROUNDUP(MONTH(D10)/3,0) -> 4 | G10: Öğren-Dönüş | H10: Saha Çalışması | I10: Enart Emaye | J10: KMF-2025-ÖDP-89-137 | K10: Kayseri | L10: 4 | M10: 10 | N10: =IFERROR(L10/8," ") -> 0.5 | O10: =M10*L10 -> 40 | P10: =+M10*N10 -> 5
A11: Ebru Takcı | B11: Tam Zamanlı | C11: Uzman | D11: 46000 | E11: =+YEAR(D11) -> 2025 | F11: =+ROUNDUP(MONTH(D11)/3,0) -> 4 | G11: Öğren-Dönüş | H11: Saha Çalışması | I11: Enart Emaye | J11: KMF-2025-ÖDP-89-137 | K11: Kayseri | L11: 4 | M11: 10 | N11: =IFERROR(L11/8," ") -> 0.5 | O11: =M11*L11 -> 40 | P11: =+M11*N11 -> 5
A12: Onur Kemaneci | B12: Tam Zamanlı | C12: Stajyer | D12: 46001 | E12: =+YEAR(D12) -> 2025 | F12: =+ROUNDUP(MONTH(D12)/3,0) -> 4 | G12: Butik Proje | H12: Saha Çalışması | I12: Parteks | J12: KMF-2024-BUP-12-122 | K12: Kayseri | L12: 4 | M12: 10 | N12: =IFERROR(L12/8," ") -> 0.5 | O12: =M12*L12 -> 40 | P12: =+M12*N12 -> 5
A13: Ebru Takcı | B13: Tam Zamanlı | C13: Uzman | D13: 46001 | E13: =+YEAR(D13) -> 2025 | F13: =+ROUNDUP(MONTH(D13)/3,0) -> 4 | G13: Butik Proje | H13: Saha Çalışması | I13: Parteks | J13: KMF-2024-BUP-12-122 | K13: Kayseri | L13: 4 | M13: 10 | N13: =IFERROR(L13/8," ") -> 0.5 | O13: =M13*L13 -> 40 | P13: =+M13*N13 -> 5
A14: Mehmet Sürücü | B14: Tam Zamanlı | C14: Uzman | D14: 46002 | E14: 2025 | F14: =+ROUNDUP(MONTH(D14)/3,0) -> 4 | G14: Öğren-Dönüş | H14: Saha Çalışması | I14: Enart Emaye | J14: KMF-2025-ÖDP-89-137 | K14: Kayseri | L14: 8 | M14: 10 | N14: =IFERROR(L14/8," ") -> 1 | O14: =M14*L14 -> 80 | P14: =+M14*N14 -> 10
A15: Ebru Takcı | B15: Tam Zamanlı | C15: Uzman | D15: 46002 | E15: =+YEAR(D15) -> 2025 | F15: =+ROUNDUP(MONTH(D15)/3,0) -> 4 | G15: Öğren-Dönüş | H15: Saha Çalışması | I15: Enart Emaye | J15: KMF-2025-ÖDP-89-137 | K15: Kayseri | L15: 8 | M15: 10 | N15: =IFERROR(L15/8," ") -> 1 | O15: =M15*L15 -> 80 | P15: =+M15*N15 -> 10
A16: Ezgi Bayburtgil | B16: Tam Zamanlı | C16: Stajyer | D16: 46002 | E16: =+YEAR(D16) -> 2025 | F16: =+ROUNDUP(MONTH(D16)/3,0) -> 4 | G16: Öğren-Dönüş | H16: Saha Çalışması | I16: Enart Emaye | J16: KMF-2025-ÖDP-89-137 | K16: Kayseri | L16: 8 | M16: 10 | N16: =IFERROR(L16/8," ") -> 1 | O16: =M16*L16 -> 80 | P16: =+M16*N16 -> 10
A17: Zehra Mumcu | B17: Tam Zamanlı | C17: Stajyer | D17: 46002 | E17: =+YEAR(D17) -> 2025 | F17: =+ROUNDUP(MONTH(D17)/3,0) -> 4 | G17: Öğren-Dönüş | H17: Saha Çalışması | I17: Enart Emaye | J17: KMF-2025-ÖDP-89-137 | K17: Kayseri | L17: 8 | M17: 10 | N17: =IFERROR(L17/8," ") -> 1 | O17: =M17*L17 -> 80 | P17: =+M17*N17 -> 10
A18: Ebru Takcı | B18: Tam Zamanlı | C18: Uzman | D18: 46003 | E18: =+YEAR(D18) -> 2025 | F18: =+ROUNDUP(MONTH(D18)/3,0) -> 4 | G18: Öğren-Dönüş | H18: Saha Çalışması | I18: Akyapı Lojistik | J18: KMF-2025-ÖDP-87-135 | K18: Kayseri | L18: 8 | M18: 10 | N18: =IFERROR(L18/8," ") -> 1 | O18: =M18*L18 -> 80 | P18: =+M18*N18 -> 10
A19: Ezgi Bayburtgil | B19: Tam Zamanlı | C19: Stajyer | D19: 46003 | E19: =+YEAR(D19) -> 2025 | F19: =+ROUNDUP(MONTH(D19)/3,0) -> 4 | G19: Öğren-Dönüş | H19: Saha Çalışması | I19: Akyapı Lojistik | J19: KMF-2025-ÖDP-89-135 | K19: Kayseri | L19: 8 | M19: 10 | N19: =IFERROR(L19/8," ") -> 1 | O19: =M19*L19 -> 80 | P19: =+M19*N19 -> 10
A20: Zehra Mumcu | B20: Tam Zamanlı | C20: Stajyer | D20: 46003 | E20: =+YEAR(D20) -> 2025 | F20: =+ROUNDUP(MONTH(D20)/3,0) -> 4 | G20: Öğren-Dönüş | H20: Saha Çalışması | I20: Akyapı Lojistik | J20: KMF-2025-ÖDP-89-135 | K20: Kayseri | L20: 8 | M20: 10 | N20: =IFERROR(L20/8," ") -> 1 | O20: =M20*L20 -> 80 | P20: =+M20*N20 -> 10
A21: Burak Ciğer | B21: Tam Zamanlı | C21: Stajyer | D21: 46003 | E21: =+YEAR(D21) -> 2025 | F21: =+ROUNDUP(MONTH(D21)/3,0) -> 4 | G21: Öğren-Dönüş | H21: Saha Çalışması | I21: Akyapı Lojistik | J21: KMF-2025-ÖDP-89-135 | K21: Kayseri | L21: 8 | M21: 10 | N21: =IFERROR(L21/8," ") -> 1 | O21: =M21*L21 -> 80 | P21: =+M21*N21 -> 10
A22: Ebru Takcı | B22: Tam Zamanlı | C22: Uzman | D22: 46006 | E22: =+YEAR(D22) -> 2025 | F22: =+ROUNDUP(MONTH(D22)/3,0) -> 4 | G22: Öğren-Dönüş | H22: Saha Çalışması | I22: Kilim Mobilya | J22: KMF-2025-BUP-13-140 | K22: Kayseri | L22: 4 | M22: 10 | N22: =IFERROR(L22/8," ") -> 0.5 | O22: =M22*L22 -> 40 | P22: =+M22*N22 -> 5
A23: Mehmet Sürücü | B23: Tam Zamanlı | C23: Uzman | D23: 46006 | E23: 2025 | F23: =+ROUNDUP(MONTH(D23)/3,0) -> 4 | G23: Öğren-Dönüş | H23: Saha Çalışması | I23: Kilim Mobilya | J23: KMF-2025-BUP-13-140 | K23: Kayseri | L23: 4 | M23: 10 | N23: =IFERROR(L23/8," ") -> 0.5 | O23: =M23*L23 -> 40 | P23: =+M23*N23 -> 5
A24: Ebru Takcı | B24: Tam Zamanlı | C24: Uzman | D24: 46006 | E24: =+YEAR(D24) -> 2025 | F24: =+ROUNDUP(MONTH(D24)/3,0) -> 4 | G24: Butik Proje | H24: Saha Çalışması | I24: Parteks | J24: KMF-2024-BUP-12-122 | K24: Kayseri | L24: 4 | M24: 10 | N24: =IFERROR(L24/8," ") -> 0.5 | O24: =M24*L24 -> 40 | P24: =+M24*N24 -> 5

Sheet Özet Durum
A1: No | B1: Proje No | C1: Danışmanlık Alan Firma | D1: Firmanın İli | E1: Faaliyet Alanı | F1: Danışman | G1: Danışman Türü | H1: Klasör Yeri | I1: Danışmanlık Türü | J1: Danışmanlık Durumu | K1: Başlangıç Tarihi | L1: Başlangıç Yıl | M1: Planlanan Bitiş Tarihi | N1: Gerçekleşen Bitiş Tarihi | O1: Projenin Tamamlanacağı Gün Sayısı | P1: Projenin Gerçekleşen Gün Sayısı | Q1: Bitiş Yılı | R1: Plana Uyum Oranı | S1: Plan. İş Günü | T1: Ger. İş Günü | U1: Kalan İş Günü | V1: Durum | W1: Proje Yıllık Getirisi | X1: ANKET ZAMANI | Y1: Memnuniyet Oranı
A2: 1 | B2: KMF-2021-ÖDP-01-001 | C2: Comfytex | D2: Kayseri | E2: Tekstil | F2: Ebru Takcı | G2: Tam Zamanlı | H2: ÖD-1 | I2: Öğren Dönüş | J2: =+IF(V2=1,"Tamamlandı","Devam Ediyor") -> #REF! | K2: =VLOOKUP(B2,#REF!,2,0) -> #REF! | L2: =YEAR(K2) -> #REF! | M2: =+K2+O2 -> #REF! | N2: =VLOOKUP(B2,#REF!,2,0) -> #REF! | O2: 150 | P2: =+N2-K2 -> #REF! | Q2: =+YEAR(N2) -> #REF! | R2: =IF(P2<O2,1,1-(ABS(O2-P2)/O2)) -> #REF! | S2: 20 | T2: =+SUMIF(#REF!,'Özet Durum'!B2,#REF!) -> #REF! | U2: =+S2-T2 -> #REF! | V2: =+T2/S2 -> #REF! | W2: 12000000 | X2: =IF(T2<S2/2," ",IF(T2=S2/2,"1.Anket Zamanı Geldi",IF(T2>S2/2,"2.Anket Zamanı Geldi"))) -> #REF! | Y2: 0.99
A3: 2 | B3: KMF-2021-ÖDP-02-002 | C3: Decoyat | D3: Kayseri | E3: Mobilya | F3: Furkan Yiğit | G3: Tam Zamanlı | H3: ÖD-1 | I3: Öğren Dönüş | J3: =+IF(V3=1,"Tamamlandı","Devam Ediyor") -> #REF! | K3: =VLOOKUP(B3,#REF!,2,0) -> #REF! | L3: =YEAR(K3) -> #REF! | M3: =+K3+O3 -> #REF! | N3: =VLOOKUP(B3,#REF!,2,0) -> #REF! | O3: 150 | P3: =+N3-K3 -> #REF! | Q3: =+YEAR(N3) -> #REF! | R3: =IF(P3<O3,1,1-(ABS(O3-P3)/O3)) -> #REF! | S3: 15 | T3: =+SUMIF(#REF!,'Özet Durum'!B3,#REF!) -> #REF! | U3: =+S3-T3 -> #REF! | V3: =+T3/S3 -> #REF! | W3: 4200000 | X3: =IF(T3<S3/2," ",IF(T3=S3/2,"1.Anket Zamanı Geldi",IF(T3>S3/2,"2.Anket Zamanı Geldi"))) -> #REF! | Y3: 0.95
A4: 3 | B4: KMF-2021-ÖDP-03-003 | C4: Efor Çelik Kapı | D4: Kayseri | E4: Metal | F4: Emre Koşar | G4: Tam Zamanlı | H4: ÖD-1 | I4: Öğren Dönüş | J4: =+IF(V4=1,"Tamamlandı","Devam Ediyor") -> #REF! | K4: =VLOOKUP(B4,#REF!,2,0) -> #REF! | L4: =YEAR(K4) -> #REF! | M4: =+K4+O4 -> #REF! | N4: =VLOOKUP(B4,#REF!,2,0) -> #REF! | O4: 150 | P4: =+N4-K4 -> #REF! | Q4: =+YEAR(N4) -> #REF! | R4: =IF(P4<O4,1,1-(ABS(O4-P4)/O4)) -> #REF! | S4: 17 | T4: =+SUMIF(#REF!,'Özet Durum'!B4,#REF!) -> #REF! | U4: =+S4-T4 -> #REF! | V4: =+T4/S4 -> #REF! | W4: 1620000 | X4: =IF(T4<S4/2," ",IF(T4=S4/2,"1.Anket Zamanı Geldi",IF(T4>S4/2,"2.Anket Zamanı Geldi"))) -> #REF! | Y4: 1
A5: 4 | B5: KMF-2021-ÖDP-04-004 | C5: Milenyum Metal | D5: Kayseri | E5: Metal | F5: Emre Koşar | G5: Tam Zamanlı | H5: ÖD-1 | I5: Öğren Dönüş | J5: =+IF(V5=1,"Tamamlandı","Devam Ediyor") -> #REF! | K5: =VLOOKUP(B5,#REF!,2,0) -> #REF! | L5: =YEAR(K5) -> #REF! | M5: =+K5+O5 -> #REF! | N5: =VLOOKUP(B5,#REF!,2,0) -> #REF! | O5: 150 | P5: =+N5-K5 -> #REF! | Q5: =+YEAR(N5) -> #REF! | R5: =IF(P5<O5,1,1-(ABS(O5-P5)/O5)) -> #REF! | S5: 15 | T5: =+SUMIF(#REF!,'Özet Durum'!B5,#REF!) -> #REF! | U5: =+S5-T5 -> #REF! | V5: =+T5/S5 -> #REF! | W5: 7290000 | X5: =IF(T5<S5/2," ",IF(T5=S5/2,"1.Anket Zamanı Geldi",IF(T5>S5/2,"2.Anket Zamanı Geldi"))) -> #REF! | Y5: 0.93
A6: 5 | B6: KMF-2021-ÖDP-05-005 | C6: Mywin | D6: Kayseri | E6: PVC | F6: Ebru Takcı | G6: Tam Zamanlı | H6: ÖD-1 | I6: Öğren Dönüş | J6: =+IF(V6=1,"Tamamlandı","Devam Ediyor") -> #REF! | K6: =VLOOKUP(B6,#REF!,2,0) -> #REF! | L6: =YEAR(K6) -> #REF! | M6: =+K6+O6 -> #REF! | N6: =VLOOKUP(B6,#REF!,2,0) -> #REF! | O6: 150 | P6: =+N6-K6 -> #REF! | Q6: =+YEAR(N6) -> #REF! | R6: =IF(P6<O6,1,1-(ABS(O6-P6)/O6)) -> #REF! | S6: 16 | T6: =+SUMIF(#REF!,'Özet Durum'!B6,#REF!) -> #REF! | U6: =+S6-T6 -> #REF! | V6: =+T6/S6 -> #REF! | W6: 1875000 | X6: =IF(T6<S6/2," ",IF(T6=S6/2,"1.Anket Zamanı Geldi",IF(T6>S6/2,"2.Anket Zamanı Geldi"))) -> #REF!
A7: 6 | B7: KMF-2021-ÖDP-06-006 | C7: Ödül Madeni Eşya | D7: Kayseri | E7: Beyaz Eşya | F7: Furkan Yiğit | G7: Tam Zamanlı | H7: ÖD-1 | I7: Öğren Dönüş | J7: =+IF(V7=1,"Tamamlandı","Devam Ediyor") -> #REF! | K7: =VLOOKUP(B7,#REF!,2,0) -> #REF! | L7: =YEAR(K7) -> #REF! | M7: =+K7+O7 -> #REF! | N7: =VLOOKUP(B7,#REF!,2,0) -> #REF! | O7: 150 | P7: =+N7-K7 -> #REF! | Q7: =+YEAR(N7) -> #REF! | R7: =IF(P7<O7,1,1-(ABS(O7-P7)/O7)) -> #REF! | S7: 17 | T7: =+SUMIF(#REF!,'Özet Durum'!B7,#REF!) -> #REF! | U7: =+S7-T7 -> #REF! | V7: =+T7/S7 -> #REF! | W7: 7800000 | X7: =IF(T7<S7/2," ",IF(T7=S7/2,"1.Anket Zamanı Geldi",IF(T7>S7/2,"2.Anket Zamanı Geldi"))) -> #REF! | Y7: 0.98
A8: 7 | B8: KMF-2021-VKO-01-007 | C8: Almila Mobilya | D8: Kayseri | E8: Mobilya | F8: Adem Göleç | G8: Yarı Zamanlı | H8: ÖD-2 | I8: VKO | J8: =+IF(V8=1,"Tamamlandı","Devam Ediyor") -> #REF! | K8: =VLOOKUP(B8,#REF!,2,0) -> #REF! | L8: =YEAR(K8) -> #REF! | M8: =+K8+O8 -> #REF! | N8: =VLOOKUP(B8,#REF!,2,0) -> #REF! | O8: 90 | P8: =+N8-K8 -> #REF! | Q8: =+YEAR(N8) -> #REF! | R8: =IF(P8<O8,1,1-(ABS(O8-P8)/O8)) -> #REF! | S8: 12 | T8: =+SUMIF(#REF!,'Özet Durum'!B8,#REF!) -> #REF! | U8: =+S8-T8 -> #REF! | V8: =+T8/S8 -> #REF! | W8: 1347500 | X8: =IF(T8<S8/2," ",IF(T8=S8/2,"1.Anket Zamanı Geldi",IF(T8>S8/2,"2.Anket Zamanı Geldi"))) -> #REF! | Y8: 0.73
A9: 8 | B9: KMF-2021-VKO-02-008 | C9: Sar Profil | D9: Kayseri | E9: Mobilya | F9: Furkan Yiğit | G9: Tam Zamanlı | H9: ÖD-3 | I9: VKO | J9: =+IF(V9=1,"Tamamlandı","Devam Ediyor") -> #REF! | K9: =VLOOKUP(B9,#REF!,2,0) -> #REF! | L9: =YEAR(K9) -> #REF! | M9: =+K9+O9 -> #REF! | N9: =VLOOKUP(B9,#REF!,2,0) -> #REF! | O9: 90 | P9: =+N9-K9 -> #REF! | Q9: =+YEAR(N9) -> #REF! | R9: =IF(P9<O9,1,1-(ABS(O9-P9)/O9)) -> #REF! | S9: 12 | T9: =+SUMIF(#REF!,'Özet Durum'!B9,#REF!) -> #REF! | U9: =+S9-T9 -> #REF! | V9: =+T9/S9 -> #REF! | W9: 313932 | X9: =IF(T9<S9/2," ",IF(T9=S9/2,"1.Anket Zamanı Geldi",IF(T9>S9/2,"2.Anket Zamanı Geldi"))) -> #REF! | Y9: 1
A10: 9 | B10: KMF-2021-VKO-03-009 | C10: Mondi | D10: Kayseri | E10: Mobilya | F10: Emre Koşar | G10: Tam Zamanlı | H10: ÖD-2 | I10: VKO | J10: =+IF(V10=1,"Tamamlandı","Devam Ediyor") -> #REF! | K10: =VLOOKUP(B10,#REF!,2,0) -> #REF! | L10: =YEAR(K10) -> #REF! | M10: =+K10+O10 -> #REF! | N10: =VLOOKUP(B10,#REF!,2,0) -> #REF! | O10: 90 | P10: =+N10-K10 -> #REF! | Q10: =+YEAR(N10) -> #REF! | R10: =IF(P10<O10,1,1-(ABS(O10-P10)/O10)) -> #REF! | S10: 12 | T10: =+SUMIF(#REF!,'Özet Durum'!B10,#REF!) -> #REF! | U10: =+S10-T10 -> #REF! | V10: =+T10/S10 -> #REF! | W10: 534000 | X10: =IF(T10<S10/2," ",IF(T10=S10/2,"1.Anket Zamanı Geldi",IF(T10>S10/2,"2.Anket Zamanı Geldi"))) -> #REF! | Y10: 0.96
A11: 10 | B11: KMF-2021-VKO-04-010 | C11: Mundo | D11: Kayseri | E11: Mobilya | F11: Beyza Kaçar | G11: Tam Zamanlı | H11: ÖD-3 | I11: VKO | J11: =+IF(V11=1,"Tamamlandı","Devam Ediyor") -> #REF! | K11: =VLOOKUP(B11,#REF!,2,0) -> #REF! | L11: =YEAR(K11) -> #REF! | M11: =+K11+O11 -> #REF! | N11: =VLOOKUP(B11,#REF!,2,0) -> #REF! | O11: 90 | P11: =+N11-K11 -> #REF! | Q11: =+YEAR(N11) -> #REF! | R11: =IF(P11<O11,1,1-(ABS(O11-P11)/O11)) -> #REF! | S11: 12 | T11: =+SUMIF(#REF!,'Özet Durum'!B11,#REF!) -> #REF! | U11: =+S11-T11 -> #REF! | V11: =+T11/S11 -> #REF! | W11: 0 | X11: =IF(T11<S11/2," ",IF(T11=S11/2,"1.Anket Zamanı Geldi",IF(T11>S11/2,"2.Anket Zamanı Geldi"))) -> #REF! | Y11: 0.84
A12: 11 | B12: KMF-2021-VKO-05-011 | C12: Serhat | D12: Kayseri | E12: Mobilya | F12: İsmet Söylemez | G12: Yarı Zamanlı | H12: ÖD-2 | I12: VKO | J12: =+IF(V12=1,"Tamamlandı","Devam Ediyor") -> #REF! | K12: =VLOOKUP(B12,#REF!,2,0) -> #REF! | L12: =YEAR(K12) -> #REF! | M12: =+K12+O12 -> #REF! | N12: =VLOOKUP(B12,#REF!,2,0) -> #REF! | O12: 90 | P12: =+N12-K12 -> #REF! | Q12: =+YEAR(N12) -> #REF! | R12: =IF(P12<O12,1,1-(ABS(O12-P12)/O12)) -> #REF! | S12: 12 | T12: =+SUMIF(#REF!,'Özet Durum'!B12,#REF!) -> #REF! | U12: =+S12-T12 -> #REF! | V12: =+T12/S12 -> #REF! | W12: 352000 | X12: =IF(T12<S12/2," ",IF(T12=S12/2,"1.Anket Zamanı Geldi",IF(T12>S12/2,"2.Anket Zamanı Geldi"))) -> #REF!
A13: 12 | B13: KMF-2021-VKO-06-012 | C13: Viva | D13: Kayseri | E13: Mobilya | F13: Erdal Yaylacı | G13: Yarı Zamanlı | H13: ÖD-3 | I13: VKO | J13: =+IF(V13=1,"Tamamlandı","Devam Ediyor") -> #REF! | K13: =VLOOKUP(B13,#REF!,2,0) -> #REF! | L13: =YEAR(K13) -> #REF! | M13: =+K13+O13 -> #REF! | N13: =VLOOKUP(B13,#REF!,2,0) -> #REF! | O13: 90 | P13: =+N13-K13 -> #REF! | Q13: =+YEAR(N13) -> #REF! | R13: =IF(P13<O13,1,1-(ABS(O13-P13)/O13)) -> #REF! | S13: 12 | T13: =+SUMIF(#REF!,'Özet Durum'!B13,#REF!) -> #REF! | U13: =+S13-T13 -> #REF! | V13: =+T13/S13 -> #REF! | W13: 3847000 | X13: =IF(T13<S13/2," ",IF(T13=S13/2,"1.Anket Zamanı Geldi",IF(T13>S13/2,"2.Anket Zamanı Geldi"))) -> #REF! | Y13: 0.98
A14: 13 | B14: KMF-2021-VKO-07-013 | C14: Yataş | D14: Kayseri | E14: Mobilya | F14: Ebru Takcı | G14: Tam Zamanlı | H14: ÖD-2 | I14: VKO | J14: =+IF(V14=1,"Tamamlandı","Devam Ediyor") -> #REF! | K14: =VLOOKUP(B14,#REF!,2,0) -> #REF! | L14: =YEAR(K14) -> #REF! | M14: =+K14+O14 -> #REF! | N14: =VLOOKUP(B14,#REF!,2,0) -> #REF! | O14: 90 | P14: =+N14-K14 -> #REF! | Q14: =+YEAR(N14) -> #REF! | R14: =IF(P14<O14,1,1-(ABS(O14-P14)/O14)) -> #REF! | S14: 12 | T14: =+SUMIF(#REF!,'Özet Durum'!B14,#REF!) -> #REF! | U14: =+S14-T14 -> #REF! | V14: =+T14/S14 -> #REF! | W14: 3240000 | X14: =IF(T14<S14/2," ",IF(T14=S14/2,"1.Anket Zamanı Geldi",IF(T14>S14/2,"2.Anket Zamanı Geldi"))) -> #REF! | Y14: 0.98
A15: 14 | B15: KMF-2021-ÖDP-07-014 | C15: Armor | D15: Çorum | E15: Otomotiv Yan Sanayi | F15: Emre Koşar | G15: Tam Zamanlı | H15: ÖD-4 | I15: Öğren Dönüş | J15: =+IF(V15=1,"Tamamlandı","Devam Ediyor") -> #REF! | K15: =VLOOKUP(B15,#REF!,2,0) -> #REF! | L15: =YEAR(K15) -> #REF! | M15: =+K15+O15 -> #REF! | N15: =VLOOKUP(B15,#REF!,2,0) -> #REF! | O15: 150 | P15: =+N15-K15 -> #REF! | Q15: =+YEAR(N15) -> #REF! | R15: =IF(P15<O15,1,1-(ABS(O15-P15)/O15)) -> #REF! | S15: 18 | T15: =+SUMIF(#REF!,'Özet Durum'!B15,#REF!) -> #REF! | U15: =+S15-T15 -> #REF! | V15: =+T15/S15 -> #REF! | W15: 5352000 | X15: =IF(T15<S15/2," ",IF(T15=S15/2,"1.Anket Zamanı Geldi",IF(T15>S15/2,"2.Anket Zamanı Geldi"))) -> #REF! | Y15: 0.98
A16: 15 | B16: KMF-2021-ÖDP-08-015 | C16: Badem Pınarı | D16: Kırşehir | E16: Gıda | F16: Emre Koşar | G16: Tam Zamanlı | H16: ÖD-8 | I16: Öğren Dönüş | J16: =+IF(V16=1,"Tamamlandı","Devam Ediyor") -> #REF! | K16: =VLOOKUP(B16,#REF!,2,0) -> #REF! | L16: =YEAR(K16) -> #REF! | M16: =+K16+O16 -> #REF! | N16: =VLOOKUP(B16,#REF!,2,0) -> #REF! | O16: 150 | P16: =+N16-K16 -> #REF! | Q16: =+YEAR(N16) -> #REF! | R16: =IF(P16<O16,1,1-(ABS(O16-P16)/O16)) -> #REF! | S16: 20 | T16: =+SUMIF(#REF!,'Özet Durum'!B16,#REF!) -> #REF! | U16: =+S16-T16 -> #REF! | V16: =+T16/S16 -> #REF! | W16: 2550000 | X16: =IF(T16<S16/2," ",IF(T16=S16/2,"1.Anket Zamanı Geldi",IF(T16>S16/2,"2.Anket Zamanı Geldi"))) -> #REF! | Y16: 1
A17: 16 | B17: KMF-2021-ÖDP-09-016 | C17: Çelebi Kardeşler | D17: Aksaray | E17: Tekstil | F17: Furkan Yiğit | G17: Tam Zamanlı | H17: ÖD-8 | I17: Öğren Dönüş | J17: =+IF(V17=1,"Tamamlandı","Devam Ediyor") -> #REF! | K17: =VLOOKUP(B17,#REF!,2,0) -> #REF! | L17: =YEAR(K17) -> #REF! | M17: =+K17+O17 -> #REF! | N17: =VLOOKUP(B17,#REF!,2,0) -> #REF! | O17: 150 | P17: =+N17-K17 -> #REF! | Q17: =+YEAR(N17) -> #REF! | R17: =IF(P17<O17,1,1-(ABS(O17-P17)/O17)) -> #REF! | S17: 20 | T17: =+SUMIF(#REF!,'Özet Durum'!B17,#REF!) -> #REF! | U17: =+S17-T17 -> #REF! | V17: =+T17/S17 -> #REF! | W17: 0 | X17: =IF(T17<S17/2," ",IF(T17=S17/2,"1.Anket Zamanı Geldi",IF(T17>S17/2,"2.Anket Zamanı Geldi"))) -> #REF! | Y17: 1
A18: 17 | B18: KMF-2021-ÖDP-10-017 | C18: Formal Alüminyum | D18: Kayseri | E18: Metal | F18: Ebru Takcı | G18: Tam Zamanlı | H18: ÖD-4 | I18: Öğren Dönüş | J18: =+IF(V18=1,"Tamamlandı","Devam Ediyor") -> #REF! | K18: =VLOOKUP(B18,#REF!,2,0) -> #REF! | L18: =YEAR(K18) -> #REF! | M18: =+K18+O18 -> #REF! | N18: =VLOOKUP(B18,#REF!,2,0) -> #REF! | O18: 150 | P18: =+N18-K18 -> #REF! | Q18: =+YEAR(N18) -> #REF! | R18: =IF(P18<O18,1,1-(ABS(O18-P18)/O18)) -> #REF! | S18: 8 | T18: =+SUMIF(#REF!,'Özet Durum'!B18,#REF!) -> #REF! | U18: =+S18-T18 -> #REF! | V18: =+T18/S18 -> #REF! | W18: 0 | X18: =IF(T18<S18/2," ",IF(T18=S18/2,"1.Anket Zamanı Geldi",IF(T18>S18/2,"2.Anket Zamanı Geldi"))) -> #REF!
A19: 18 | B19: KMF-2021-ÖDP-11-018 | C19: Hedef Kablo | D19: Kayseri | E19: Metal | F19: Emre Koşar | G19: Tam Zamanlı | H19: ÖD-5 | I19: Öğren Dönüş | J19: =+IF(V19=1,"Tamamlandı","Devam Ediyor") -> #REF! | K19: =VLOOKUP(B19,#REF!,2,0) -> #REF! | L19: =YEAR(K19) -> #REF! | M19: =+K19+O19 -> #REF! | N19: =VLOOKUP(B19,#REF!,2,0) -> #REF! | O19: 250 | P19: =+N19-K19 -> #REF! | Q19: =+YEAR(N19) -> #REF! | R19: =IF(P19<O19,1,1-(ABS(O19-P19)/O19)) -> #REF! | S19: 19 | T19: =+SUMIF(#REF!,'Özet Durum'!B19,#REF!) -> #REF! | U19: =+S19-T19 -> #REF! | V19: =+T19/S19 -> #REF! | W19: =18000000-W14 -> 14760000 | X19: =IF(T19<S19/2," ",IF(T19=S19/2,"1.Anket Zamanı Geldi",IF(T19>S19/2,"2.Anket Zamanı Geldi"))) -> #REF! | Y19: 1
A20: 19 | B20: KMF-2021-ÖDP-12-019 | C20: Somçelik | D20: Kayseri | E20: Metal | F20: Beyza Kaçar | G20: Tam Zamanlı | H20: ÖD-5 | I20: Öğren Dönüş | J20: =+IF(V20=1,"Tamamlandı","Devam Ediyor") -> #REF! | K20: =VLOOKUP(B20,#REF!,2,0) -> #REF! | L20: =YEAR(K20) -> #REF! | M20: =+K20+O20 -> #REF! | N20: =VLOOKUP(B20,#REF!,2,0) -> #REF! | O20: 150 | P20: =+N20-K20 -> #REF! | Q20: =+YEAR(N20) -> #REF! | R20: =IF(P20<O20,1,1-(ABS(O20-P20)/O20)) -> #REF! | S20: 25 | T20: =+SUMIF(#REF!,'Özet Durum'!B20,#REF!) -> #REF! | U20: =+S20-T20 -> #REF! | V20: =+T20/S20 -> #REF! | W20: 1213777 | X20: =IF(T20<S20/2," ",IF(T20=S20/2,"1.Anket Zamanı Geldi",IF(T20>S20/2,"2.Anket Zamanı Geldi"))) -> #REF! | Y20: 0.94
A21: 20 | B21: KMF-2021-VKO-08-020 | C21: Formal Alüminyum | D21: Kayseri | E21: Metal | F21: Ebru Takcı | G21: Tam Zamanlı | H21: ÖD-5 | I21: VKO | J21: =+IF(V21=1,"Tamamlandı","Devam Ediyor") -> #REF! | K21: =VLOOKUP(B21,#REF!,2,0) -> #REF! | L21: =YEAR(K21) -> #REF! | M21: =+K21+O21 -> #REF! | N21: =VLOOKUP(B21,#REF!,2,0) -> #REF! | O21: 90 | P21: =+N21-K21 -> #REF! | Q21: =+YEAR(N21) -> #REF! | R21: =IF(P21<O21,1,1-(ABS(O21-P21)/O21)) -> #REF! | S21: 12 | T21: =+SUMIF(#REF!,'Özet Durum'!B21,#REF!) -> #REF! | U21: =+S21-T21 -> #REF! | V21: =+T21/S21 -> #REF! | W21: 4560000 | X21: =IF(T21<S21/2," ",IF(T21=S21/2,"1.Anket Zamanı Geldi",IF(T21>S21/2,"2.Anket Zamanı Geldi"))) -> #REF!
A22: 21 | B22: KMF-2021-VKO-09-021 | C22: Hedef Kablo | D22: Kayseri | E22: Metal | F22: Emre Koşar | G22: Tam Zamanlı | H22: ÖD-4 | I22: VKO | J22: =+IF(V22=1,"Tamamlandı","Devam Ediyor") -> #REF! | K22: =VLOOKUP(B22,#REF!,2,0) -> #REF! | L22: =YEAR(K22) -> #REF! | M22: =+K22+O22 -> #REF! | N22: =VLOOKUP(B22,#REF!,2,0) -> #REF! | O22: 90 | P22: =+N22-K22 -> #REF! | Q22: =+YEAR(N22) -> #REF! | R22: =IF(P22<O22,1,1-(ABS(O22-P22)/O22)) -> #REF! | S22: 15 | T22: =+SUMIF(#REF!,'Özet Durum'!B22,#REF!) -> #REF! | U22: =+S22-T22 -> #REF! | V22: =+T22/S22 -> #REF! | W22: 6830000 | X22: =IF(T22<S22/2," ",IF(T22=S22/2,"1.Anket Zamanı Geldi",IF(T22>S22/2,"2.Anket Zamanı Geldi"))) -> #REF! | Y22: 1
A23: 22 | B23: KMF-2021-VKO-10-022 | C23: Somçelik | D23: Kayseri | E23: Metal | F23: Beyza Kaçar | G23: Tam Zamanlı | H23: ÖD-4 | I23: VKO | J23: =+IF(V23=1,"Tamamlandı","Devam Ediyor") -> #REF! | K23: =VLOOKUP(B23,#REF!,2,0) -> #REF! | L23: =YEAR(K23) -> #REF! | M23: =+K23+O23 -> #REF! | N23: =VLOOKUP(B23,#REF!,2,0) -> #REF! | O23: 90 | P23: =+N23-K23 -> #REF! | Q23: =+YEAR(N23) -> #REF! | R23: =IF(P23<O23,1,1-(ABS(O23-P23)/O23)) -> #REF! | S23: 12.5 | T23: =+SUMIF(#REF!,'Özet Durum'!B23,#REF!) -> #REF! | U23: =+S23-T23 -> #REF! | V23: =+T23/S23 -> #REF! | W23: 969000 | X23: =IF(T23<S23/2," ",IF(T23=S23/2,"1.Anket Zamanı Geldi",IF(T23>S23/2,"2.Anket Zamanı Geldi"))) -> #REF! | Y23: 0.94
A24: 23 | B24: KMF-2021-ÖDP-13-023 | C24: Arkopa | D24: Kayseri | E24: Mobilya | F24: Ebru Takcı | G24: Tam Zamanlı | H24: ÖD-8 | I24: Öğren Dönüş | J24: =+IF(V24=1,"Tamamlandı","Devam Ediyor") -> #REF! | K24: =VLOOKUP(B24,#REF!,2,0) -> #REF! | L24: =YEAR(K24) -> #REF! | M24: =+K24+O24 -> #REF! | N24: =VLOOKUP(B24,#REF!,2,0) -> #REF! | O24: 150 | P24: =+N24-K24 -> #REF! | Q24: =+YEAR(N24) -> #REF! | R24: =IF(P24<O24,1,1-(ABS(O24-P24)/O24)) -> #REF! | S24: 23 | T24: =+SUMIF(#REF!,'Özet Durum'!B24,#REF!) -> #REF! | U24: =+S24-T24 -> #REF! | V24: =+T24/S24 -> #REF! | W24: 5250000 | X24: =IF(T24<S24/2," ",IF(T24=S24/2,"1.Anket Zamanı Geldi",IF(T24>S24/2,"2.Anket Zamanı Geldi"))) -> #REF! | Y24: 0.98
A25: 24 | B25: KMF-2021-ÖDP-14-024 | C25: Mitsan | D25: Kayseri | E25: Mobilya | F25: Furkan Yiğit | G25: Tam Zamanlı | H25: ÖD-9 | I25: Öğren Dönüş | J25: =+IF(V25=1,"Tamamlandı","Devam Ediyor") -> #REF! | K25: =VLOOKUP(B25,#REF!,2,0) -> #REF! | L25: =YEAR(K25) -> #REF! | M25: =+K25+O25 -> #REF! | N25: =VLOOKUP(B25,#REF!,2,0) -> #REF! | O25: 150 | P25: =+N25-K25 -> #REF! | Q25: =+YEAR(N25) -> #REF! | R25: =IF(P25<O25,1,1-(ABS(O25-P25)/O25)) -> #REF! | S25: 4.5 | T25: =+SUMIF(#REF!,'Özet Durum'!B25,#REF!) -> #REF! | U25: =+S25-T25 -> #REF! | V25: =+T25/S25 -> #REF! | W25: 0 | X25: =IF(T25<S25/2," ",IF(T25=S25/2,"1.Anket Zamanı Geldi",IF(T25>S25/2,"2.Anket Zamanı Geldi"))) -> #REF! | Y25: 1
A26: 25 | B26: KMF-2021-ÖDP-15-025 | C26: Sarıgözoğlu | D26: Aksaray | E26: Otomotiv Yan Sanayi | F26: Ersoy Türel | G26: Yarı Zamanlı | H26: 5.ÖD | I26: Öğren Dönüş | J26: =+IF(V26=1,"Tamamlandı","Devam Ediyor") -> Tamamlandı | K26: =VLOOKUP(B26,#REF!,2,0) -> #REF! | L26: =YEAR(K26) -> #REF! | M26: =+K26+O26 -> #REF! | N26: =VLOOKUP(B26,#REF!,2,0) -> #REF! | O26: 150 | P26: =+N26-K26 -> #REF! | Q26: =+YEAR(N26) -> #REF! | R26: =IF(P26<O26,1,1-(ABS(O26-P26)/O26)) -> #REF! | S26: 15 | T26: 15 | U26: =+S26-T26 -> 0 | V26: =+T26/S26 -> 1 | W26: 381837 | X26: =IF(T26<S26/2," ",IF(T26=S26/2,"1.Anket Zamanı Geldi",IF(T26>S26/2,"2.Anket Zamanı Geldi"))) -> 2.Anket Zamanı Geldi | Y26: 0.93
A27: 26 | B27: KMF-2021-VKO-11-026 | C27: Arkopa | D27: Kayseri | E27: Mobilya | F27: Ebru Takcı | G27: Tam Zamanlı | H27: ÖD-7 | I27: VKO | J27: =+IF(V27=1,"Tamamlandı","Devam Ediyor") -> #REF! | K27: =VLOOKUP(B27,#REF!,2,0) -> #REF! | L27: =YEAR(K27) -> #REF! | M27: =+K27+O27 -> #REF! | N27: =VLOOKUP(B27,#REF!,2,0) -> #REF! | O27: 90 | P27: =+N27-K27 -> #REF! | Q27: =+YEAR(N27) -> #REF! | R27: =IF(P27<O27,1,1-(ABS(O27-P27)/O27)) -> #REF! | S27: 12 | T27: =+SUMIF(#REF!,'Özet Durum'!B27,#REF!) -> #REF! | U27: =+S27-T27 -> #REF! | V27: =+T27/S27 -> #REF! | W27: =793500*2 -> 1587000 | X27: =IF(T27<S27/2," ",IF(T27=S27/2,"1.Anket Zamanı Geldi",IF(T27>S27/2,"2.Anket Zamanı Geldi"))) -> #REF! | Y27: 0.98
A28: 27 | B28: KMF-2021-VKO-12-027 | C28: Büşra Kaçan (Paşa) | D28: Kayseri | E28: Mobilya | F28: Erdal Yaylacı | G28: Yarı Zamanlı | H28: ÖD-6 | I28: VKO | J28: =+IF(V28=1,"Tamamlandı","Devam Ediyor") -> #REF! | K28: =VLOOKUP(B28,#REF!,2,0) -> #REF! | L28: =YEAR(K28) -> #REF! | M28: =+K28+O28 -> #REF! | N28: =VLOOKUP(B28,#REF!,2,0) -> #REF! | O28: 90 | P28: =+N28-K28 -> #REF! | Q28: =+YEAR(N28) -> #REF! | R28: =IF(P28<O28,1,1-(ABS(O28-P28)/O28)) -> #REF! | S28: 9 | T28: =+SUMIF(#REF!,'Özet Durum'!B28,#REF!) -> #REF! | U28: =+S28-T28 -> #REF! | V28: =+T28/S28 -> #REF! | W28: 660000 | X28: =IF(T28<S28/2," ",IF(T28=S28/2,"1.Anket Zamanı Geldi",IF(T28>S28/2,"2.Anket Zamanı Geldi"))) -> #REF!
A29: 28 | B29: KMF-2021-VKO-13-028 | C29: Doqu | D29: Kayseri | E29: Mobilya | F29: Erdal Yaylacı | G29: Yarı Zamanlı | H29: ÖD-7 | I29: VKO | J29: =+IF(V29=1,"Tamamlandı","Devam Ediyor") -> #REF! | K29: =VLOOKUP(B29,#REF!,2,0) -> #REF! | L29: =YEAR(K29) -> #REF! | M29: =+K29+O29 -> #REF! | N29: =VLOOKUP(B29,#REF!,2,0) -> #REF! | O29: 90 | P29: =+N29-K29 -> #REF! | Q29: =+YEAR(N29) -> #REF! | R29: =IF(P29<O29,1,1-(ABS(O29-P29)/O29)) -> #REF! | S29: 9 | T29: =+SUMIF(#REF!,'Özet Durum'!B29,#REF!) -> #REF! | U29: =+S29-T29 -> #REF! | V29: =+T29/S29 -> #REF! | W29: 2237440 | X29: =IF(T29<S29/2," ",IF(T29=S29/2,"1.Anket Zamanı Geldi",IF(T29>S29/2,"2.Anket Zamanı Geldi"))) -> #REF! | Y29: 0.91
A30: 29 | B30: KMF-2021-VKO-14-029 | C30: Elizan | D30: Kayseri | E30: Mobilya | F30: Adem Göleç | G30: Yarı Zamanlı | H30: ÖD-7 | I30: VKO | J30: =+IF(V30=1,"Tamamlandı","Devam Ediyor") -> #REF! | K30: =VLOOKUP(B30,#REF!,2,0) -> #REF! | L30: =YEAR(K30) -> #REF! | M30: =+K30+O30 -> #REF! | N30: =VLOOKUP(B30,#REF!,2,0) -> #REF! | O30: 90 | P30: =+N30-K30 -> #REF! | Q30: =+YEAR(N30) -> #REF! | R30: =IF(P30<O30,1,1-(ABS(O30-P30)/O30)) -> #REF! | S30: 10 | T30: =+SUMIF(#REF!,'Özet Durum'!B30,#REF!) -> #REF! | U30: =+S30-T30 -> #REF! | V30: =+T30/S30 -> #REF! | W30: 0 | X30: =IF(T30<S30/2," ",IF(T30=S30/2,"1.Anket Zamanı Geldi",IF(T30>S30/2,"2.Anket Zamanı Geldi"))) -> #REF!
A31: 30 | B31: KMF-2021-VKO-15-030 | C31: Ergül | D31: Kayseri | E31: Mobilya | F31: Furkan Yiğit | G31: Tam Zamanlı | H31: ÖD-7 | I31: VKO | J31: =+IF(V31=1,"Tamamlandı","Devam Ediyor") -> #REF! | K31: =VLOOKUP(B31,#REF!,2,0) -> #REF! | L31: =YEAR(K31) -> #REF! | M31: =+K31+O31 -> #REF! | N31: =VLOOKUP(B31,#REF!,2,0) -> #REF! | O31: 90 | P31: =+N31-K31 -> #REF! | Q31: =+YEAR(N31) -> #REF! | R31: =IF(P31<O31,1,1-(ABS(O31-P31)/O31)) -> #REF! | S31: 12 | T31: =+SUMIF(#REF!,'Özet Durum'!B31,#REF!) -> #REF! | U31: =+S31-T31 -> #REF! | V31: =+T31/S31 -> #REF! | W31: 779712 | X31: =IF(T31<S31/2," ",IF(T31=S31/2,"1.Anket Zamanı Geldi",IF(T31>S31/2,"2.Anket Zamanı Geldi"))) -> #REF! | Y31: 1
A32: 31 | B32: KMF-2021-VKO-16-031 | C32: Ladin | D32: Kayseri | E32: Mobilya | F32: Ebru Takcı | G32: Tam Zamanlı | H32: ÖD-6 | I32: VKO | J32: =+IF(V32=1,"Tamamlandı","Devam Ediyor") -> #REF! | K32: =VLOOKUP(B32,#REF!,2,0) -> #REF! | L32: =YEAR(K32) -> #REF! | M32: =+K32+O32 -> #REF! | N32: =VLOOKUP(B32,#REF!,2,0) -> #REF! | O32: 90 | P32: =+N32-K32 -> #REF! | Q32: =+YEAR(N32) -> #REF! | R32: =IF(P32<O32,1,1-(ABS(O32-P32)/O32)) -> #REF! | S32: 12 | T32: =+SUMIF(#REF!,'Özet Durum'!B32,#REF!) -> #REF! | U32: =+S32-T32 -> #REF! | V32: =+T32/S32 -> #REF! | W32: 881192 | X32: =IF(T32<S32/2," ",IF(T32=S32/2,"1.Anket Zamanı Geldi",IF(T32>S32/2,"2.Anket Zamanı Geldi"))) -> #REF! | Y32: 0.98
A33: 32 | B33: KMF-2021-VKO-17-032 | C33: Lükssan | D33: Kayseri | E33: Mobilya | F33: Furkan Yiğit | G33: Tam Zamanlı | H33: ÖD-6 | I33: VKO | J33: =+IF(V33=1,"Tamamlandı","Devam Ediyor") -> #REF! | K33: =VLOOKUP(B33,#REF!,2,0) -> #REF! | L33: =YEAR(K33) -> #REF! | M33: =+K33+O33 -> #REF! | N33: =VLOOKUP(B33,#REF!,2,0) -> #REF! | O33: 90 | P33: =+N33-K33 -> #REF! | Q33: =+YEAR(N33) -> #REF! | R33: =IF(P33<O33,1,1-(ABS(O33-P33)/O33)) -> #REF! | S33: 12 | T33: =+SUMIF(#REF!,'Özet Durum'!B33,#REF!) -> #REF! | U33: =+S33-T33 -> #REF! | V33: =+T33/S33 -> #REF! | W33: 5265000 | X33: =IF(T33<S33/2," ",IF(T33=S33/2,"1.Anket Zamanı Geldi",IF(T33>S33/2,"2.Anket Zamanı Geldi"))) -> #REF! | Y33: 0.77
A34: 33 | B34: KMF-2021-VKO-18-033 | C34: Mitsan | D34: Kayseri | E34: Mobilya | F34: Furkan Yiğit | G34: Tam Zamanlı | H34: ÖD-8 | I34: VKO | J34: =+IF(V34=1,"Tamamlandı","Devam Ediyor") -> #REF! | K34: =VLOOKUP(B34,#REF!,2,0) -> #REF! | L34: =YEAR(K34) -> #REF! | M34: =+K34+O34 -> #REF! | N34: =VLOOKUP(B34,#REF!,2,0) -> #REF! | O34: 90 | P34: =+N34-K34 -> #REF! | Q34: =+YEAR(N34) -> #REF! | R34: =IF(P34<O34,1,1-(ABS(O34-P34)/O34)) -> #REF! | S34: 15 | T34: =+SUMIF(#REF!,'Özet Durum'!B34,#REF!) -> #REF! | U34: =+S34-T34 -> #REF! | V34: =+T34/S34 -> #REF! | W34: 0 | X34: =IF(T34<S34/2," ",IF(T34=S34/2,"1.Anket Zamanı Geldi",IF(T34>S34/2,"2.Anket Zamanı Geldi"))) -> #REF! | Y34: 1
A35: 34 | B35: KMF-2021-VKO-19-034 | C35: Zeytin | D35: Kayseri | E35: Mobilya | F35: Batuhan Kızılışık | G35: Yarı Zamanlı | H35: ÖD-6 | I35: VKO | J35: =+IF(V35=1,"Tamamlandı","Devam Ediyor") -> #REF! | K35: =VLOOKUP(B35,#REF!,2,0) -> #REF! | L35: =YEAR(K35) -> #REF! | M35: =+K35+O35 -> #REF! | N35: =VLOOKUP(B35,#REF!,2,0) -> #REF! | O35: 90 | P35: =+N35-K35 -> #REF! | Q35: =+YEAR(N35) -> #REF! | R35: =IF(P35<O35,1,1-(ABS(O35-P35)/O35)) -> #REF! | S35: 10 | T35: =+SUMIF(#REF!,'Özet Durum'!B35,#REF!) -> #REF! | U35: =+S35-T35 -> #REF! | V35: =+T35/S35 -> #REF! | W35: 900000 | X35: =IF(T35<S35/2," ",IF(T35=S35/2,"1.Anket Zamanı Geldi",IF(T35>S35/2,"2.Anket Zamanı Geldi"))) -> #REF! | Y35: 0.96
A36: 35 | B36: KMF-2022-ÖDP-16-035 | C36: Çemens | D36: Kayseri | E36: Gıda | F36: Emre Koşar | G36: Tam Zamanlı | H36: ÖD-10 | I36: Öğren Dönüş | J36: =+IF(V36=1,"Tamamlandı","Devam Ediyor") -> #REF! | K36: =VLOOKUP(B36,#REF!,2,0) -> #REF! | L36: =YEAR(K36) -> #REF! | M36: =+K36+O36 -> #REF! | N36: =VLOOKUP(B36,#REF!,2,0) -> #REF! | O36: 150 | P36: =+N36-K36 -> #REF! | Q36: =+YEAR(N36) -> #REF! | R36: =IF(P36<O36,1,1-(ABS(O36-P36)/O36)) -> #REF! | S36: 10 | T36: =+SUMIF(#REF!,'Özet Durum'!B36,#REF!) -> #REF! | U36: =+S36-T36 -> #REF! | V36: =+T36/S36 -> #REF! | W36: 925000 | X36: =IF(T36<S36/2," ",IF(T36=S36/2,"1.Anket Zamanı Geldi",IF(T36>S36/2,"2.Anket Zamanı Geldi"))) -> #REF!
A37: 36 | B37: KMF-2022-ÖDP-17-036 | C37: Kayseri Yem | D37: Kayseri | E37: Hayvansal Gıda | F37: Erdal Yaylacı | G37: Yarı Zamanlı | H37: ÖD-10 | I37: Öğren Dönüş | J37: =+IF(V37=1,"Tamamlandı","Devam Ediyor") -> #REF! | K37: =VLOOKUP(B37,#REF!,2,0) -> #REF! | L37: =YEAR(K37) -> #REF! | M37: =+K37+O37 -> #REF! | N37: =VLOOKUP(B37,#REF!,2,0) -> #REF! | O37: 210 | P37: =+N37-K37 -> #REF! | Q37: =+YEAR(N37) -> #REF! | R37: =IF(P37<O37,1,1-(ABS(O37-P37)/O37)) -> #REF! | S37: 20 | T37: =+SUMIF(#REF!,'Özet Durum'!B37,#REF!) -> #REF! | U37: =+S37-T37 -> #REF! | V37: =+T37/S37 -> #REF! | W37: 0 | X37: =IF(T37<S37/2," ",IF(T37=S37/2,"1.Anket Zamanı Geldi",IF(T37>S37/2,"2.Anket Zamanı Geldi"))) -> #REF!
A38: 37 | B38: KMF-2022-ÖDP-18-037 | C38: Yataş | D38: Kayseri | E38: Mobilya | F38: Ebru Takcı | G38: Tam Zamanlı | H38: ÖD-10 | I38: Öğren Dönüş | J38: =+IF(V38=1,"Tamamlandı","Devam Ediyor") -> #REF! | K38: =VLOOKUP(B38,#REF!,2,0) -> #REF! | L38: =YEAR(K38) -> #REF! | M38: =+K38+O38 -> #REF! | N38: =VLOOKUP(B38,#REF!,2,0) -> #REF! | O38: 210 | P38: =+N38-K38 -> #REF! | Q38: =+YEAR(N38) -> #REF! | R38: =IF(P38<O38,1,1-(ABS(O38-P38)/O38)) -> #REF! | S38: 14 | T38: =+SUMIF(#REF!,'Özet Durum'!B38,#REF!) -> #REF! | U38: =+S38-T38 -> #REF! | V38: =+T38/S38 -> #REF! | W38: 2500000 | X38: =IF(T38<S38/2," ",IF(T38=S38/2,"1.Anket Zamanı Geldi",IF(T38>S38/2,"2.Anket Zamanı Geldi"))) -> #REF! | Y38: 0.97
A39: 38 | B39: KMF-2022-VKO-20-038 | C39: Aydın Madeni (Şamdan) | D39: Kayseri | E39: Beyaz Eşya | F39: Ersoy Türel | G39: Yarı Zamanlı | H39: ÖD-9 | I39: VKO | J39: =+IF(V39=1,"Tamamlandı","Devam Ediyor") -> #REF! | K39: =VLOOKUP(B39,#REF!,2,0) -> #REF! | L39: =YEAR(K39) -> #REF! | M39: =+K39+O39 -> #REF! | N39: =VLOOKUP(B39,#REF!,2,0) -> #REF! | O39: 90 | P39: =+N39-K39 -> #REF! | Q39: =+YEAR(N39) -> #REF! | R39: =IF(P39<O39,1,1-(ABS(O39-P39)/O39)) -> #REF! | S39: 13 | T39: =+SUMIF(#REF!,'Özet Durum'!B39,#REF!) -> #REF! | U39: =+S39-T39 -> #REF! | V39: =+T39/S39 -> #REF! | W39: 987624 | X39: =IF(T39<S39/2," ",IF(T39=S39/2,"1.Anket Zamanı Geldi",IF(T39>S39/2,"2.Anket Zamanı Geldi"))) -> #REF!
A40: 39 | B40: KMF-2022-VKO-21-039 | C40: Everest | D40: Kayseri | E40: Metal | F40: Erdal Yaylacı | G40: Yarı Zamanlı | H40: ÖD-9 | I40: VKO | J40: =+IF(V40=1,"Tamamlandı","Devam Ediyor") -> #REF! | K40: =VLOOKUP(B40,#REF!,2,0) -> #REF! | L40: =YEAR(K40) -> #REF! | M40: =+K40+O40 -> #REF! | N40: =VLOOKUP(B40,#REF!,2,0) -> #REF! | O40: 90 | P40: =+N40-K40 -> #REF! | Q40: =+YEAR(N40) -> #REF! | R40: =IF(P40<O40,1,1-(ABS(O40-P40)/O40)) -> #REF! | S40: 9 | T40: =+SUMIF(#REF!,'Özet Durum'!B40,#REF!) -> #REF! | U40: =+S40-T40 -> #REF! | V40: =+T40/S40 -> #REF! | W40: 1718000 | X40: =IF(T40<S40/2," ",IF(T40=S40/2,"1.Anket Zamanı Geldi",IF(T40>S40/2,"2.Anket Zamanı Geldi"))) -> #REF! | Y40: 0.97
...
